Workbook

Sheet Dashboard Resumen
B2: Resumen Ejecutivo y KPIs de Inventario
B4: Total Productos Únicos | D4: =COUNTA('Catálogo Maestro'!A3:A68)
B5: Unidades Totales en Stock | D5: ='Catálogo Maestro'!E69
B6: Valorización de Inventario | D6: ='Catálogo Maestro'!J69
B7: Precio Unitario Promedio | D7: =AVERAGE('Catálogo Maestro'!D3:D68)
B10: Distribución por Categoría
B11: Categoría | C11: Valor Inventario
B12: Electrónica | C12: =SUMIF('Catálogo Maestro'!C3:C68, B12, 'Catálogo Maestro'!J3:J68)
B13: Audio | C13: =SUMIF('Catálogo Maestro'!C3:C68, B13, 'Catálogo Maestro'!J3:J68)
B14: Accesorios | C14: =SUMIF('Catálogo Maestro'!C3:C68, B14, 'Catálogo Maestro'!J3:J68)
B15: Mobiliario | C15: =SUMIF('Catálogo Maestro'!C3:C68, B15, 'Catálogo Maestro'!J3:J68)
B16: Hogar | C16: =SUMIF('Catálogo Maestro'!C3:C68, B16, 'Catálogo Maestro'!J3:J68)

Sheet Catálogo Maestro
A2: ID Producto | B2: Nombre de Producto | C2: Categoría | D2: Precio Unitario (MXN) | E2: Stock | F2: ID Tienda | G2: Proveedor | H2: Fecha Ingreso | I2: Estado | J2: Valor Total Inventario
A3: PROD-5001 | B3: Laptop Gamer Alpha - Estándar | C3: Electrónica | D3: 13381 | E3: 116 | F3: México | G3: LogiTech Dist. | H3: 2025-09-18 | I3: =IF(ISBLANK(E3), "Sin Verificar", IF(E3=0, "Agotado", IF(E3<=15, "Bajo Stock", "Disponible"))) | J3: =IF(ISBLANK(E3), 0, D3*E3)
A4: PROD-5002 | B4: Laptop Gamer Alpha - Pro | C4: Electrónica | D4: 31723 | E4: 27 | F4: México | G4: Global Audio SA | H4: 2025-09-09 | I4: =IF(ISBLANK(E4), "Sin Verificar", IF(E4=0, "Agotado", IF(E4<=15, "Bajo Stock", "Disponible"))) | J4: =IF(ISBLANK(E4), 0, D4*E4)
A5: PROD-5003 | B5: Laptop Gamer Alpha - Enterprise | C5: Electrónica | D5: 30227 | E5: 56 | F5: mex | G5: LogiTech Dist. | H5: 2026-02-22 | I5: =IF(ISBLANK(E5), "Sin Verificar", IF(E5=0, "Agotado", IF(E5<=15, "Bajo Stock", "Disponible"))) | J5: =IF(ISBLANK(E5), 0, D5*E5)
A6: PROD-5004 | B6: Smartphone UltraV - Estándar | C6: Electrónica | D6: 21588 | E6: 98 | F6: mex | G6: Muebles del Norte | H6: 2025-09-16 | I6: =IF(ISBLANK(E6), "Sin Verificar", IF(E6=0, "Agotado", IF(E6<=15, "Bajo Stock", "Disponible"))) | J6: =IF(ISBLANK(E6), 0, D6*E6)
A7: PROD-5005 | B7: Smartphone UltraV - Pro | C7: Electrónica | D7: 20013 | E7: 81 | F7: mexico | G7: LogiTech Dist. | H7: 2026-01-29 | I7: =IF(ISBLANK(E7), "Sin Verificar", IF(E7=0, "Agotado", IF(E7<=15, "Bajo Stock", "Disponible"))) | J7: =IF(ISBLANK(E7), 0, D7*E7)
A8: PROD-5006 | B8: Smartphone UltraV - Enterprise | C8: Electrónica | D8: 35861 | E8: 59 | F8: MX | G8: Muebles del Norte | H8: 2025-11-28 | I8: =IF(ISBLANK(E8), "Sin Verificar", IF(E8=0, "Agotado", IF(E8<=15, "Bajo Stock", "Disponible"))) | J8: =IF(ISBLANK(E8), 0, D8*E8)
A9: PROD-5007 | B9: Monitor Pro 32" - Estándar | C9: Electrónica | D9: 19931 | E9: 100 | F9: mexico | G9: ElectroHogar Express | H9: 2026-04-06 | I9: =IF(ISBLANK(E9), "Sin Verificar", IF(E9=0, "Agotado", IF(E9<=15, "Bajo Stock", "Disponible"))) | J9: =IF(ISBLANK(E9), 0, D9*E9)
A10: PROD-5008 | B10: Monitor Pro 32" - Pro | C10: Electrónica | D10: 27959 | E10: 0 | F10: mex | G10: LogiTech Dist. | H10: 2025-08-15 | I10: =IF(ISBLANK(E10), "Sin Verificar", IF(E10=0, "Agotado", IF(E10<=15, "Bajo Stock", "Disponible"))) | J10: =IF(ISBLANK(E10), 0, D10*E10)
A11: PROD-5009 | B11: Monitor Pro 32" - Enterprise | C11: Electrónica | D11: 31145 | F11: México | G11: Muebles del Norte | H11: 2026-05-11 | I11: =IF(ISBLANK(E11), "Sin Verificar", IF(E11=0, "Agotado", IF(E11<=15, "Bajo Stock", "Disponible"))) | J11: =IF(ISBLANK(E11), 0, D11*E11)
A12: PROD-5010 | B12: Tablet Touch 11" - Estándar | C12: Electrónica | D12: 12025 | E12: 4 | F12: México | G12: Global Audio SA | H12: 2026-04-12 | I12: =IF(ISBLANK(E12), "Sin Verificar", IF(E12=0, "Agotado", IF(E12<=15, "Bajo Stock", "Disponible"))) | J12: =IF(ISBLANK(E12), 0, D12*E12)
A13: PROD-5011 | B13: Tablet Touch 11" - Pro | C13: Electrónica | D13: 27351 | E13: 87 | F13: México | G13: ElectroHogar Express | H13: 2025-07-28 | I13: =IF(ISBLANK(E13), "Sin Verificar", IF(E13=0, "Agotado", IF(E13<=15, "Bajo Stock", "Disponible"))) | J13: =IF(ISBLANK(E13), 0, D13*E13)
A14: PROD-5012 | B14: Tablet Touch 11" - Enterprise | C14: Electrónica | D14: 21165 | E14: 63 | F14: México | G14: TechImports MX | H14: 2026-02-12 | I14: =IF(ISBLANK(E14), "Sin Verificar", IF(E14=0, "Agotado", IF(E14<=15, "Bajo Stock", "Disponible"))) | J14: =IF(ISBLANK(E14), 0, D14*E14)
A15: PROD-5013 | B15: Consola Nexus X - Estándar | C15: Electrónica | D15: 7194 | E15: 10 | F15: México | G15: ElectroHogar Express | H15: 2025-08-15 | I15: =IF(ISBLANK(E15), "Sin Verificar", IF(E15=0, "Agotado", IF(E15<=15, "Bajo Stock", "Disponible"))) | J15: =IF(ISBLANK(E15), 0, D15*E15)
A16: PROD-5014 | B16: Consola Nexus X - Pro | C16: Electrónica | D16: 14708 | E16: 86 | F16: mexico | G16: Global Audio SA | H16: 2026-03-05 | I16: =IF(ISBLANK(E16), "Sin Verificar", IF(E16=0, "Agotado", IF(E16<=15, "Bajo Stock", "Disponible"))) | J16: =IF(ISBLANK(E16), 0, D16*E16)
A17: PROD-5015 | B17: Consola Nexus X - Enterprise | C17: Electrónica | D17: 23087 | E17: 94 | F17: mexico | G17: LogiTech Dist. | H17: 2026-03-05 | I17: =IF(ISBLANK(E17), "Sin Verificar", IF(E17=0, "Agotado", IF(E17<=15, "Bajo Stock", "Disponible"))) | J17: =IF(ISBLANK(E17), 0, D17*E17)
A18: PROD-5016 | B18: Smartwatch Fit - Estándar | C18: Electrónica | D18: 11914 | E18: 113 | F18: mexico | G18: LogiTech Dist. | H18: 2026-04-11 | I18: =IF(ISBLANK(E18), "Sin Verificar", IF(E18=0, "Agotado", IF(E18<=15, "Bajo Stock", "Disponible"))) | J18: =IF(ISBLANK(E18), 0, D18*E18)
A19: PROD-5017 | B19: Smartwatch Fit - Pro | C19: Electrónica | D19: 24949 | E19: 59 | F19: México | G19: LogiTech Dist. | H19: 2025-11-29 | I19: =IF(ISBLANK(E19), "Sin Verificar", IF(E19=0, "Agotado", IF(E19<=15, "Bajo Stock", "Disponible"))) | J19: =IF(ISBLANK(E19), 0, D19*E19)
A20: PROD-5018 | B20: Smartwatch Fit - Enterprise | C20: Electrónica | D20: 27502 | E20: 119 | F20: mexico | G20: ElectroHogar Express | H20: 2026-01-31 | I20: =IF(ISBLANK(E20), "Sin Verificar", IF(E20=0, "Agotado", IF(E20<=15, "Bajo Stock", "Disponible"))) | J20: =IF(ISBLANK(E20), 0, D20*E20)
A21: PROD-5019 | B21: Auriculares ANC Pro - Estándar | C21: Audio | D21: 859 | E21: 67 | F21: México | G21: LogiTech Dist. | H21: 2026-01-10 | I21: =IF(ISBLANK(E21), "Sin Verificar", IF(E21=0, "Agotado", IF(E21<=15, "Bajo Stock", "Disponible"))) | J21: =IF(ISBLANK(E21), 0, D21*E21)
A22: PROD-5020 | B22: Auriculares ANC Pro - Pro | C22: Audio | D22: 2091 | E22: 83 | F22: mex | G22: LogiTech Dist. | H22: 2026-05-09 | I22: =IF(ISBLANK(E22), "Sin Verificar", IF(E22=0, "Agotado", IF(E22<=15, "Bajo Stock", "Disponible"))) | J22: =IF(ISBLANK(E22), 0, D22*E22)
A23: PROD-5021 | B23: Auriculares ANC Pro - Enterprise | C23: Audio | D23: 5086 | E23: 50 | F23: mexico | G23: LogiTech Dist. | H23: 2025-07-28 | I23: =IF(ISBLANK(E23), "Sin Verificar", IF(E23=0, "Agotado", IF(E23<=15, "Bajo Stock", "Disponible"))) | J23: =IF(ISBLANK(E23), 0, D23*E23)
... A31: PROD-5029 | B31: Altavoz Exterior Waterproof - Pro | C31: Audio | D31: 4602 | E31: 32 | F31: mexico | G31: ElectroHogar Express | H31: 2026-01-31 | I31: =IF(ISBLANK(E31), "Sin Verificar", IF(E31=0, "Agotado", IF(E31<=15, "Bajo Stock", "Disponible"))) | J31: =IF(ISBLANK(E31), 0, D31*E31)
A32: PROD-5030 | B32: Altavoz Exterior Waterproof - Enterprise | C32: Audio | D32: 2747 | F32: MX | G32: ElectroHogar Express | H32: 2025-11-21 | I32: =IF(ISBLANK(E32), "Sin Verificar", IF(E32=0, "Agotado", IF(E32<=15, "Bajo Stock", "Disponible"))) | J32: =IF(ISBLANK(E32), 0, D32*E32)
A33: PROD-5031 | B33: Teclado Mecánico Pro - Estándar | C33: Accesorios | D33: 2196 | E33: 85 | F33: mex | G33: ElectroHogar Express | H33: 2026-04-28 | I33: =IF(ISBLANK(E33), "Sin Verificar", IF(E33=0, "Agotado", IF(E33<=15, "Bajo Stock", "Disponible"))) | J33: =IF(ISBLANK(E33), 0, D33*E33)
A34: PROD-5032 | B34: Teclado Mecánico Pro - Pro | C34: Accesorios | D34: 3959 | E34: 118 | F34: MX | G34: ElectroHogar Express | H34: 2025-10-17 | I34: =IF(ISBLANK(E34), "Sin Verificar", IF(E34=0, "Agotado", IF(E34<=15, "Bajo Stock", "Disponible"))) | J34: =IF(ISBLANK(E34), 0, D34*E34)
A35: PROD-5033 | B35: Teclado Mecánico Pro - Enterprise | C35: Accesorios | D35: 5326 | E35: 35 | F35: mex | G35: LogiTech Dist. | H35: 2025-09-08 | I35: =IF(ISBLANK(E35), "Sin Verificar", IF(E35=0, "Agotado", IF(E35<=15, "Bajo Stock", "Disponible"))) | J35: =IF(ISBLANK(E35), 0, D35*E35)
A36: PROD-5034 | B36: Mouse Óptico Ergo - Estándar | C36: Accesorios | D36: 545 | E36: 88 | F36: MX | G36: TechImports MX | H36: 2026-04-01 | I36: =IF(ISBLANK(E36), "Sin Verificar", IF(E36=0, "Agotado", IF(E36<=15, "Bajo Stock", "Disponible"))) | J36: =IF(ISBLANK(E36), 0, D36*E36)
A37: PROD-5035 | B37: Mouse Óptico Ergo - Pro | C37: Accesorios | D37: 3026 | E37: 43 | F37: MX | G37: ElectroHogar Express | H37: 2026-03-01 | I37: =IF(ISBLANK(E37), "Sin Verificar", IF(E37=0, "Agotado", IF(E37<=15, "Bajo Stock", "Disponible"))) | J37: =IF(ISBLANK(E37), 0, D37*E37)
A38: PROD-5036 | B38: Mouse Óptico Ergo - Enterprise | C38: Accesorios | D38: 5649 | E38: 53 | F38: MX | G38: Muebles del Norte | H38: 2026-01-13 | I38: =IF(ISBLANK(E38), "Sin Verificar", IF(E38=0, "Agotado", IF(E38<=15, "Bajo Stock", "Disponible"))) | J38: =IF(ISBLANK(E38), 0, D38*E38)
A39: PROD-5037 | B39: Hub Multi-puerto USB-C - Estándar | C39: Accesorios | D39: 1287 | E39: 82 | F39: MX | G39: Global Audio SA | H39: 2026-01-17 | I39: =IF(ISBLANK(E39), "Sin Verificar", IF(E39=0, "Agotado", IF(E39<=15, "Bajo Stock", "Disponible"))) | J39: =IF(ISBLANK(E39), 0, D39*E39)
A40: PROD-5038 | B40: Hub Multi-puerto USB-C - Pro | C40: Accesorios | D40: 4140 | E40: 20 | F40: mex | G40: Global Audio SA | H40: 2025-09-28 | I40: =IF(ISBLANK(E40), "Sin Verificar", IF(E40=0, "Agotado", IF(E40<=15, "Bajo Stock", "Disponible"))) | J40: =IF(ISBLANK(E40), 0, D40*E40)
A41: PROD-5039 | B41: Hub Multi-puerto USB-C - Enterprise | C41: Accesorios | D41: 941 | E41: 24 | F41: mex | G41: TechImports MX | H41: 2026-03-23 | I41: =IF(ISBLANK(E41), "Sin Verificar", IF(E41=0, "Agotado", IF(E41<=15, "Bajo Stock", "Disponible"))) | J41: =IF(ISBLANK(E41), 0, D41*E41)
A42: PROD-5040 | B42: Cargador GaN 100W - Estándar | C42: Accesorios | D42: 2560 | F42: mex | G42: ElectroHogar Express | H42: 2025-07-24 | I42: =IF(ISBLANK(E42), "Sin Verificar", IF(E42=0, "Agotado", IF(E42<=15, "Bajo Stock", "Disponible"))) | J42: =IF(ISBLANK(E42), 0, D42*E42)
A43: PROD-5041 | B43: Cargador GaN 100W - Pro | C43: Accesorios | D43: 1251 | E43: 14 | F43: MX | G43: TechImports MX | H43: 2025-09-28 | I43: =IF(ISBLANK(E43), "Sin Verificar", IF(E43=0, "Agotado", IF(E43<=15, "Bajo Stock", "Disponible"))) | J43: =IF(ISBLANK(E43), 0, D43*E43)
A44: PROD-5042 | B44: Cargador GaN 100W - Enterprise | C44: Accesorios | D44: 4652 | E44: 91 | F44: MX | G44: ElectroHogar Express | H44: 2025-12-26 | I44: =IF(ISBLANK(E44), "Sin Verificar", IF(E44=0, "Agotado", IF(E44<=15, "Bajo Stock", "Disponible"))) | J44: =IF(ISBLANK(E44), 0, D44*E44)
A45: PROD-5043 | B45: Mochila Ejecutiva Tech - Estándar | C45: Accesorios | D45: 3487 | E45: 17 | F45: MX | G45: TechImports MX | H45: 2025-12-19 | I45: =IF(ISBLANK(E45), "Sin Verificar", IF(E45=0, "Agotado", IF(E45<=15, "Bajo Stock", "Disponible"))) | J45: =IF(ISBLANK(E45), 0, D45*E45)
A46: PROD-5044 | B46: Mochila Ejecutiva Tech - Pro | C46: Accesorios | D46: 881 | E46: 12 | F46: mex | G46: ElectroHogar Express | H46: 2026-02-20 | I46: =IF(ISBLANK(E46), "Sin Verificar", IF(E46=0, "Agotado", IF(E46<=15, "Bajo Stock", "Disponible"))) | J46: =IF(ISBLANK(E46), 0, D46*E46)
A47: PROD-5045 | B47: Mochila Ejecutiva Tech - Enterprise | C47: Accesorios | D47: 5246 | E47: 71 | F47: México | G47: Global Audio SA | H47: 2026-04-29 | I47: =IF(ISBLANK(E47), "Sin Verificar", IF(E47=0, "Agotado", IF(E47<=15, "Bajo Stock", "Disponible"))) | J47: =IF(ISBLANK(E47), 0, D47*E47)
A48: PROD-5046 | B48: Silla Ergonómica Premium - Estándar | C48: Mobiliario | D48: 3997 | E48: 49 | F48: mexico | G48: Global Audio SA | H48: 2026-01-11 | I48: =IF(ISBLANK(E48), "Sin Verificar", IF(E48=0, "Agotado", IF(E48<=15, "Bajo Stock", "Disponible"))) | J48: =IF(ISBLANK(E48), 0, D48*E48)
...
